<?xml version="1.0" ?>
<robot name="ROV">

<material name="black">
	<color rgba="0 0 0 1"/>
</material>

    <link name="link1" >
        <gravity>0</gravity>
        <visual>
            <origin rpy="0 0 0" xyz="0 0 0" />
            <geometry>
            <sphere radius="0.3" />
            
            </geometry>
        
        </visual>
        <inertial>
            <mass value="0.00001"/>
            <origin xyz="0 0 0"/>
            <inertia ixx="0.1" ixy="1.44" ixz="0" iyy="0.1" iyz="2.6" izz="0.1"/>
        </inertial>
        <collision>
            <origin rpy="0 1.57075 0" xyz="0 0 -0.3"/>
            <geometry>
            <box size="0.5 0.3 0.5"/>
            </geometry>
            <material name="black"/>
        </collision>
        <neutrally_buoyant>0</neutrally_buoyant>
        <volume>1000</volume>


    </link>

    <link name="link2" >
        <gravity>0</gravity>
        <visual>
            <origin rpy="0 1.57075 0" xyz="0 0 -0.3"/>
            <geometry>
            <box size="0.5 0.3 0.5"/>
            </geometry>
            <material name="black"/>
        </visual>
        <inertial>
            <mass value="0.00001"/>
            <origin xyz="0 0 0"/>
            <inertia ixx="0.1" ixy="1.44" ixz="0" iyy="0.1" iyz="2.6" izz="0.1"/>
        </inertial>
        <neutrally_buoyant>0</neutrally_buoyant>
        <volume>1000</volume>


    </link>

    <link name="link3" >
        <gravity>0</gravity>
        <visual>
            <origin rpy="0 1.57075 0" xyz="0 0 -0.3"/>
            <geometry>
            <box size="0.5 0.3 0.5"/>
            </geometry>
            <material name="black"/>
        </visual>
        <inertial>
            <mass value="0.00001"/>
            <origin xyz="0 0 0"/>
            <inertia ixx="0.1" ixy="1.44" ixz="0" iyy="0.1" iyz="2.6" izz="0.1"/>
        </inertial>
        <collision>
            <origin rpy="0 1.57075 0" xyz="0 0 -0.3"/>
            <geometry>
            <box size="0.5 0.3 0.5"/>
            </geometry>
            <material name="black"/>
        </collision>

        <neutrally_buoyant>0</neutrally_buoyant>
        <volume>1000</volume>

    </link>
    


    <joint name="joint1" type="continuous">
        <parent link="link1"/>
        <child link="link2"/>
        <origin xyz="0 -0.22 0.25" rpy="0 0 0" />
        <axis xyz="-0.9 0.15 0" />
    </joint>

    <joint name="joint2" type="continuous">
        <parent link="link1"/>
        <child link="link3"/>
        <origin xyz="0 0.22 0.25" rpy="0 0 0" />
        <axis xyz="0.9 0.15 0" />
    </joint>

    <gazebo reference  = "link1">
    </gazebo>
    

    

 </robot>
